Workbook
Name ItemCodeList: Inventory!$A$5:$A$604
Name VendorList: 'Shop Summary'!$F$5:$F$35

Sheet Dashboard
A1: PAWFECT BD — BUSINESS TRACKER
A2: Overview of cash, stock and profit. All figures pull live from the other sheets.
A4: CASH POSITION
A5: Total Investment (Tk) | B5: =SUM(Investment!$C$5:$C$204) -> 345000
A6: Total Purchases / Cash Out (Tk) | B6: =SUM(Purchases!$I$5:$I$1004) -> 370966.55
A7: Total Expenses / Cash Out (Tk) | B7: =SUM(Expenses!$D$5:$D$1004) -> 42722
A8: Total Sales Revenue / Cash In (Tk) | B8: =SUM(Sales!$L$7:$L$1506) -> 147710.01
A9: Less: Amount Due from Customers (Tk) | B9: =SUMIFS(Sales!$L$7:$L$1506,Sales!$M$7:$M$1506,"Due") -> 6812.004
A10: Cash In: money collected from shops (Tk) | B10: =SUM('Shop Collections'!$C$5:$C$504) -> 13500
A11: CASH ON HAND (Tk) | B11: =B5-B6-B7+B8-B9+B10 -> 85709.457
A13: STOCK POSITION
A14: Units Purchased (total) | B14: =SUM(Inventory!$D$5:$D$604) -> 3031
A15: Units Sold (total) | B15: =SUM(Inventory!$E$5:$E$604) -> 1005
A16: Units Returned (total) | B16: =SUM(Inventory!$F$5:$F$604) -> 1
A17: Units given to shops (total) | B17: =SUM(Inventory!$G$5:$G$604) -> 458
A18: Current Stock (units) | B18: =SUM(Inventory!$H$5:$H$604) -> 1569
A19: Current Stock Value (Tk) | B19: =SUM(Inventory!$J$5:$J$604) -> 204214.08
A20: Money shops still owe you (Tk) | B20: ='Shop Summary'!D35 -> 43713
A21: PROFIT SNAPSHOT
A22: Total Money In — customers + shops (Tk) | B22: ='Profit Share'!B14 -> 204923.01
A23: Total Money Out — product cost + delivery + running costs (Tk) | B23: ='Profit Share'!B21 -> 209579.47
A24: PROFIT / LOSS (Tk) | B24: ='Profit Share'!B7 -> -4656.4615
A25: Money customers still owe you (Tk) | B25: ='Profit Share'!B24 -> 6812.004
A26: Money shops still owe you (Tk) | B26: ='Profit Share'!B25 -> 43713
A27: Total owed to you (Tk) | B27: ='Profit Share'!B26 -> 50525.004
A28: PROFIT / LOSS TO SHARE (Tk) | B28: ='Profit Share'!B7 -> -4656.4615
A29: Mukta Mama (Investor) Share — 50% (Tk) | B29: =IF('Profit Share'!B31="","",'Profit Share'!B31)
A30: Ratul Share (Tk) | B30: =IF('Profit Share'!B33="","",'Profit Share'!B33)
A31: Samin Share (Tk) | B31: =IF('Profit Share'!B34="","",'Profit Share'!B34)
A32: Nawroz Share (Tk) | B32: =IF('Profit Share'!B35="","",'Profit Share'!B35)
A34: FREE GIFTS & DISCOUNTS GIVEN AWAY | C34: Already counted in the profit above — shown so you can see it
A35: Free gifts — cost to you (Tk) | B35: ='Profit Share'!B38 -> 428.32671
A36: Free gifts — value at shop price (Tk) | B36: ='Profit Share'!B39 -> 880
A37: Discounts given on sales (Tk) | B37: ='Profit Share'!B40 -> 13504.989
A38: TOTAL GIVEN AWAY (Tk) | B38: ='Profit Share'!B41 -> 13933.316 | C38: ='Profit Share'!C41 -> That is 6.8 out of every Tk 100 of sales
A41: INVESTOR CASH POSITION
A42: Investor | B42: Invested (Tk) | C42: % of Capital | D42: Share of Purchases (Tk) | E42: Share of Expenses (Tk) | F42: Remaining Cash Share (Tk)
A43: {=IFERROR(INDEX(Investment!$B$5:$B$204,MATCH(ROW()-42,Investment!$F$5:$F$204,0)),"")} -> Mukta Mama | B43: =IF($A43="","",SUMIF(Investment!$B$5:$B$204,$A43,Investment!$C$5:$C$204)) -> 345000 | C43: =IF($A43="","",B43/$B$5) -> 1 | D43: =IF($A43="","",C43*$B$6) -> 370966.55 | E43: =IF($A43="","",C43*$B$7) -> 42722 | F43: =IF($A43="","",B43-D43-E43) -> -68688.55
A44: {=IFERROR(INDEX(Investment!$B$5:$B$204,MATCH(ROW()-42,Investment!$F$5:$F$204,0)),"")} | B44: =IF($A44="","",SUMIF(Investment!$B$5:$B$204,$A44,Investment!$C$5:$C$204)) | C44: =IF($A44="","",B44/$B$5) | D44: =IF($A44="","",C44*$B$6) | E44: =IF($A44="","",C44*$B$7) | F44: =IF($A44="","",B44-D44-E44)
A45: {=IFERROR(INDEX(Investment!$B$5:$B$204,MATCH(ROW()-42,Investment!$F$5:$F$204,0)),"")} | B45: =IF($A45="","",SUMIF(Investment!$B$5:$B$204,$A45,Investment!$C$5:$C$204)) | C45: =IF($A45="","",B45/$B$5) | D45: =IF($A45="","",C45*$B$6) | E45: =IF($A45="","",C45*$B$7) | F45: =IF($A45="","",B45-D45-E45)
...

Sheet Investment
A1: INVESTMENT LOG
A2: MONEY STILL IN THE BUSINESS | C2: =C3-C207 -> 345000 | D2: Invested minus withdrawn
A3: TOTAL INVESTED | C3: =SUM(Investment!$C$5:$C$204) -> 345000 | D3: Type on the first empty row — the list extends by itself
A4: Date | B4: Investor | C4: Amount (Tk) | D4: Note | F4: Helper - new investor no.
A5: 46209 | B5: Mukta Mama | C5: 100000 | D5: Capital investment - Tranche 1 | F5: =IF($B5="","",IF(COUNTIF($B$5:$B5,$B5)=1,MAX($F$4:F4)+1,"")) -> 1
A6: 46216 | B6: Mukta Mama | C6: 100000 | D6: Capital investment - Tranche 2 | F6: =IF($B6="","",IF(COUNTIF($B$5:$B6,$B6)=1,MAX($F$4:F5)+1,""))
A7: 46225 | B7: Mukta Mama | C7: 100000 | D7: Capital investment - Tranche 3 | F7: =IF($B7="","",IF(COUNTIF($B$5:$B7,$B7)=1,MAX($F$4:F6)+1,""))
A8: 46243 | B8: Mukta Mama | C8: 45000 | D8: Capital investment - Tranche 4 | F8: =IF($B8="","",IF(COUNTIF($B$5:$B8,$B8)=1,MAX($F$4:F7)+1,""))
F9: =IF($B9="","",IF(COUNTIF($B$5:$B9,$B9)=1,MAX($F$4:F8)+1,""))
F10: =IF($B10="","",IF(COUNTIF($B$5:$B10,$B10)=1,MAX($F$4:F9)+1,""))
F11: =IF($B11="","",IF(COUNTIF($B$5:$B11,$B11)=1,MAX($F$4:F10)+1,""))
F12: =IF($B12="","",IF(COUNTIF($B$5:$B12,$B12)=1,MAX($F$4:F11)+1,""))
F13: =IF($B13="","",IF(COUNTIF($B$5:$B13,$B13)=1,MAX($F$4:F12)+1,""))
F14: =IF($B14="","",IF(COUNTIF($B$5:$B14,$B14)=1,MAX($F$4:F13)+1,""))
F15: =IF($B15="","",IF(COUNTIF($B$5:$B15,$B15)=1,MAX($F$4:F14)+1,""))
F16: =IF($B16="","",IF(COUNTIF($B$5:$B16,$B16)=1,MAX($F$4:F15)+1,""))
F17: =IF($B17="","",IF(COUNTIF($B$5:$B17,$B17)=1,MAX($F$4:F16)+1,""))
F18: =IF($B18="","",IF(COUNTIF($B$5:$B18,$B18)=1,MAX($F$4:F17)+1,""))
F19: =IF($B19="","",IF(COUNTIF($B$5:$B19,$B19)=1,MAX($F$4:F18)+1,""))
F20: =IF($B20="","",IF(COUNTIF($B$5:$B20,$B20)=1,MAX($F$4:F19)+1,""))
... F204: =IF($B204="","",IF(COUNTIF($B$5:$B204,$B204)=1,MAX($F$4:F203)+1,""))
A206: WITHDRAWALS — money taken back out of the business
A207: TOTAL WITHDRAWN | C207: =SUM(Investment!$C$209:$C$408) -> 0
A208: Date | B208: Who took it | C208: Amount (Tk) | D208: Note

Sheet Expenses
A1: EXPENSES — Business Cash Out
A2: Log every cash expense here (rent, utilities, transport, salaries, etc.). This reduces Cash on Hand on the Dashboard.
A3: TOTALS → | D3: =SUM(Expenses!$D$5:$D$1004) -> 42722
A4: Date | B4: Category | C4: Description | D4: Amount (Tk) | E4: Notes
A5: 46216 | B5: Transport/Delivery | C5: Mirpur 11 AT Int. | D5: 180
A6: 46220 | B6: Bank/Mobile Transfer Fee | C6: Product Purchase | D6: 65
A7: 46216 | B7: Other | C7: For SmartHeart Delivery Man | D7: 100 | E7: For Bonus
A8: 46216 | B8: Other | C8: For DODO Delivery Man | D8: 50 | E8: For Bonus
A9: 46218 | B9: Transport/Delivery | C9: Product Purchase | D9: 350
A10: 46219 | B10: Transport/Delivery | C10: Product Purchase | D10: 250
A11: 46219 | B11: Maintenance | C11: Balance Sheet Khata | D11: 250
A12: 46219 | B12: Maintenance | C12: Money Box | D12: 100
A13: 46219 | B13: Marketing | C13: Facebook Boost | D13: 178
A14: 46222 | B14: Transport/Delivery | C14: Product Delivery | D14: 50 | E14: SmartHeart 2 Pc's
A15: 46222 | B15: Marketing | C15: Marketing cost | D15: 3040
A16: 46222 | B16: Transport/Delivery | C16: Transport Cost | D16: 60
A17: 46223 | B17: Marketing | C17: Banner | D17: 5000
A18: 46223 | B18: Transport/Delivery | C18: Traveling Cost for Marketing Work | D18: 20
A19: 46224 | B19: Transport/Delivery | C19: Traveling Cost for Marketing Work | D19: 40
A20: 46224 | B20: Marketing | C20: Facebook Ads | D20: 639
A21: 46224 | B21: Marketing | C21: Facebook Ads | D21: 724
A22: 46229 | B22: Transport/Delivery | C22: Transport Cost for Product Purchase | D22: 100
A23: 46229 | B23: Other | C23: For Pathao Pickup Boy | D23: 100
A24: 46229 | B24: Packaging | C24: Scotch Tape | D24: 60
A25: 46229 | B25: Maintenance | C25: Scotch Tape White | D25: 65
A26: 46229 | B26: Marketing | C26: FaceBook Marketing | D26: 125
... A55: 46252 | B55: Bank/Mobile Transfer Fee | C55: Bkash Cash Out | D55: 39

Sheet Purchases
A1: PURCHASES LOG
A2: All product purchases from suppliers. Add new rows below as you buy more.
A3: TOTALS → | G3: =SUM(Purchases!$G$5:$G$1004) -> 3031 | I3: =SUM(Purchases!$I$5:$I$1004) -> 370966.55 | K3: =SUM(Purchases!$K$5:$K$1004) -> 3031
A4: Date | B4: Type | C4: Supplier | D4: Item Code | E4: Product Description | F4: Category | G4: Qty | H4: Unit Cost (Tk) | I4: Total Cost (Tk) | J4: Website Updated | K4: Net Qty (stock calc) | L4: Helper - new item no.
A5: 46137 | B5: Purchase | C5: M.S Trading | D5: AC-PNC-LR-002 | E5: Pet Nail Clippers Large | F5: Cat Accessories | G5: 1 | H5: 190 | I5: =IF($B5="Return to Supplier",-G5*H5,G5*H5) -> 190 | J5: TRUE | K5: =IF($B5="Return to Supplier",-G5,G5) -> 1 | L5: =IF($D5="","",IF(COUNTIF($D$5:$D5,$D5)=1,MAX($L$4:L4)+1,"")) -> 1
A6: 46137 | B6: Purchase | C6: M.S Trading | D6: AC-CTOY-004 | E6: Cat Ball Robot Toy | F6: Cat Accessories | G6: 1 | H6: 95 | I6: =IF($B6="Return to Supplier",-G6*H6,G6*H6) -> 95 | J6: TRUE | K6: =IF($B6="Return to Supplier",-G6,G6) -> 1 | L6: =IF($D6="","",IF(COUNTIF($D$5:$D6,$D6)=1,MAX($L$4:L5)+1,"")) -> 2
A7: 46181 | B7: Purchase | C7: M.S Trading | D7: AC-CB-001 | E7: Cat Belt | F7: Cat Accessories | G7: 8 | H7: 27 | I7: =IF($B7="Return to Supplier",-G7*H7,G7*H7) -> 216 | J7: TRUE | K7: =IF($B7="Return to Supplier",-G7,G7) -> 8 | L7: =IF($D7="","",IF(COUNTIF($D$5:$D7,$D7)=1,MAX($L$4:L6)+1,"")) -> 3
A8: 46190 | B8: Purchase | C8: M.S Trading | D8: PO-WET-NK-70G-001 | E8: Nekko Pouch Tuna in Jelly | F8: Cat Pouch | G8: 10 | H8: 66 | I8: =IF($B8="Return to Supplier",-G8*H8,G8*H8) -> 660 | J8: TRUE | K8: =IF($B8="Return to Supplier",-G8,G8) -> 10 | L8: =IF($D8="","",IF(COUNTIF($D$5:$D8,$D8)=1,MAX($L$4:L7)+1,"")) -> 4
A9: 46190 | B9: Purchase | C9: AT International | D9: AC-CJ-AR-001 | E9: Cat Jersey Argentina Medium | F9: Cat Accessories | G9: 3 | H9: 140 | I9: =IF($B9="Return to Supplier",-G9*H9,G9*H9) -> 420 | J9: TRUE | K9: =IF($B9="Return to Supplier",-G9,G9) -> 3 | L9: =IF($D9="","",IF(COUNTIF($D$5:$D9,$D9)=1,MAX($L$4:L8)+1,"")) -> 5
A10: 46190 | B10: Purchase | C10: AT International | D10: AC-CJ-AR-002 | E10: Cat Jersey Argentina Large | F10: Cat Accessories | G10: 1 | H10: 140 | I10: =IF($B10="Return to Supplier",-G10*H10,G10*H10) -> 140 | J10: TRUE | K10: =IF($B10="Return to Supplier",-G10,G10) -> 1 | L10: =IF($D10="","",IF(COUNTIF($D$5:$D10,$D10)=1,MAX($L$4:L9)+1,"")) -> 6
A11: 46190 | B11: Purchase | C11: AT International | D11: AC-CJ-BR-002 | E11: Cat Jersey Brazil Large | F11: Cat Accessories | G11: 2 | H11: 140 | I11: =IF($B11="Return to Supplier",-G11*H11,G11*H11) -> 280 | J11: TRUE | K11: =IF($B11="Return to Supplier",-G11,G11) -> 2 | L11: =IF($D11="","",IF(COUNTIF($D$5:$D11,$D11)=1,MAX($L$4:L10)+1,"")) -> 7
A12: 46190 | B12: Purchase | C12: AT International | D12: AC-CJ-BR-001 | E12: Cat Jersey Brazil Medium | F12: Cat Accessories | G12: 3 | H12: 140 | I12: =IF($B12="Return to Supplier",-G12*H12,G12*H12) -> 420 | J12: TRUE | K12: =IF($B12="Return to Supplier",-G12,G12) -> 3 | L12: =IF($D12="","",IF(COUNTIF($D$5:$D12,$D12)=1,MAX($L$4:L11)+1,"")) -> 8
A13: 46190 | B13: Purchase | C13: AT International | D13: AC-SHAMP-002 | E13: Bengal Flea & Tick Shampoo | F13: Cat Accessories | G13: 0 | H13: 240 | I13: =IF($B13="Return to Supplier",-G13*H13,G13*H13) -> 0 | J13: TRUE | K13: =IF($B13="Return to Supplier",-G13,G13) -> 0 | L13: =IF($D13="","",IF(COUNTIF($D$5:$D13,$D13)=1,MAX($L$4:L12)+1,"")) -> 9
A14: 46190 | B14: Purchase | C14: AT International | D14: AC-SHAMP-003 | E14: Bengal Waterless Bath No-Rinse Shampoo | F14: Cat Accessories | G14: 1 | H14: 290 | I14: =IF($B14="Return to Supplier",-G14*H14,G14*H14) -> 290 | J14: TRUE | K14: =IF($B14="Return to Supplier",-G14,G14) -> 1 | L14: =IF($D14="","",IF(COUNTIF($D$5:$D14,$D14)=1,MAX($L$4:L13)+1,"")) -> 10
A15: 46190 | B15: Purchase | C15: AT International | D15: AC-LB-001 | E15: Cat Litter Box Large | F15: Cat Accessories | G15: 1 | H15: 400 | I15: =IF($B15="Return to Supplier",-G15*H15,G15*H15) -> 400 | J15: TRUE | K15: =IF($B15="Return to Supplier",-G15,G15) -> 1 | L15: =IF($D15="","",IF(COUNTIF($D$5:$D15,$D15)=1,MAX($L$4:L14)+1,"")) -> 11
A16: 46191 | B16: Purchase | C16: AT International | D16: AC-LB-002 | E16: Cat Litter Box Medium | F16: Cat Accessories | G16: 1 | H16: 300 | I16: =IF($B16="Return to Supplier",-G16*H16,G16*H16) -> 300 | J16: TRUE | K16: =IF($B16="Return to Supplier",-G16,G16) -> 1 | L16: =IF($D16="","",IF(COUNTIF($D$5:$D16,$D16)=1,MAX($L$4:L15)+1,"")) -> 12
... A151: 46249 | B151: Purchase | C151: M.S Trading | D151: FD-MX-0003 | E151: Drools, Meo & Cutie Mixed Food 100gm | F151: Cat Food | G151: 1 | H151: 31 | I151: =IF($B151="Return to Supplier",-G151*H151,G151*H151) -> 31 | J151: FALSE | K151: =IF($B151="Return to Supplier",-G151,G151) -> 1 | L151: =IF($D151="","",IF(COUNTIF($D$5:$D151,$D151)=1,MAX($L$4:L150)+1,"")) -> 121
A152: 46258 | B152: Purchase | C152: Nutrichemy Limited | D152: FD-DRY-CHNK-CHKN-1.5KG-001 | E152: Chonk All ages Tuna | F152: Cat Food | G152: 6 | H152: 400 | I152: =IF($B152="Return to Supplier",-G152*H152,G152*H152) -> 2400 | K152: =IF($B152="Return to Supplier",-G152,G152) -> 6 | L152: =IF($D152="","",IF(COUNTIF($D$5:$D152,$D152)=1,MAX($L$4:L151)+1,""))
A153: 46258 | B153: Purchase | C153: Nutrichemy Limited | D153: FD-DRY-CHNK-OCFCK-1.5KG-001 | E153: Chonk All ages Ocean Fish with Chicken | F153: Cat Food | G153: 2 | H153: 400 | I153: =IF($B153="Return to Supplier",-G153*H153,G153*H153) -> 800 | K153: =IF($B153="Return to Supplier",-G153,G153) -> 2 | L153: =IF($D153="","",IF(COUNTIF($D$5:$D153,$D153)=1,MAX($L$4:L152)+1,""))
A154: 46258 | B154: Purchase | C154: Nutrichemy Limited | D154: FD-DRY-CHNK-TN-1.5KG-001 | E154: Chonk All ages Tuna | F154: Cat Food | G154: 2 | H154: 400 | I154: =IF($B154="Return to Supplier",-G154*H154,G154*H154) -> 800 | K154: =IF($B154="Return to Supplier",-G154,G154) -> 2 | L154: =IF($D154="","",IF(COUNTIF($D$5:$D154,$D154)=1,MAX($L$4:L153)+1,""))
A155: 46260 | B155: Purchase | C155: Birds Palace | D155: FD-DRY-WP-1.5KG-001 | E155: Wanpy Grain Free Cat Food | F155: Cat Food | G155: 8 | H155: 990 | I155: =IF($B155="Return to Supplier",-G155*H155,G155*H155) -> 7920 | K155: =IF($B155="Return to Supplier",-G155,G155) -> 8 | L155: =IF($D155="","",IF(COUNTIF($D$5:$D155,$D155)=1,MAX($L$4:L154)+1,"")) -> 122
A156: 46260 | B156: Purchase | C156: Birds Palace | D156: FD-WET-WP-001 | E156: Wanpy Cat Treat Likable Tuna Mousse with Chicken 40gm | F156: Cat Wet Food | G156: 6 | H156: 80 | I156: =IF($B156="Return to Supplier",-G156*H156,G156*H156) -> 480 | K156: =IF($B156="Return to Supplier",-G156,G156) -> 6 | L156: =IF($D156="","",IF(COUNTIF($D$5:$D156,$D156)=1,MAX($L$4:L155)+1,"")) -> 123
A157: 46260 | B157: Purchase | C157: Birds Palace | D157: FD-DRY-KTCN-All-400G-001 | E157: Kitchen Flavour Grain Free Dry Cat Food All Life Stage 400gm | F157: Cat Food | G157: 16 | H157: 290 | I157: =IF($B157="Return to Supplier",-G157*H157,G157*H157) -> 4640 | K157: =IF($B157="Return to Supplier",-G157,G157) -> 16 | L157: =IF($D157="","",IF(COUNTIF($D$5:$D157,$D157)=1,MAX($L$4:L156)+1,"")) -> 124
A158: 46260 | B158: Purchase | C158: Birds Palace | D158: PO-WET-KTCN-HS-001 | E158: Kitchen Flavour Special Care Complete Cat Food Pouch Hair & Skin Care 70gm | F158: Cat Pouch | G158: 48 | H158: 75 | I158: =IF($B158="Return to Supplier",-G158*H158,G158*H158) -> 3600 | K158: =IF($B158="Return to Supplier",-G158,G158) -> 48 | L158: =IF($D158="","",IF(COUNTIF($D$5:$D158,$D158)=1,MAX($L$4:L157)+1,"")) -> 125
A159: 46260 | B159: Purchase | C159: Birds Palace | D159: PO-WET-KTCN-UR-001 | E159: Kitchen Flavour Special Care Complete Cat Food Pouch Urinary Care 70gm | F159: Cat Pouch | G159: 48 | H159: 75 | I159: =IF($B159="Return to Supplier",-G159*H159,G159*H159) -> 3600 | K159: =IF($B159="Return to Supplier",-G159,G159) -> 48 | L159: =IF($D159="","",IF(COUNTIF($D$5:$D159,$D159)=1,MAX($L$4:L158)+1,"")) -> 126
A160: 46260 | B160: Purchase | C160: Birds Palace | D160: PO-WET-KTCN-ID-001 | E160: Kitchen Flavour Special Care Complete Cat Food Pouch Indoor & Digestive Care 70gm | F160: Cat Pouch | G160: 48 | H160: 75 | I160: =IF($B160="Return to Supplier",-G160*H160,G160*H160) -> 3600 | K160: =IF($B160="Return to Supplier",-G160,G160) -> 48 | L160: =IF($D160="","",IF(COUNTIF($D$5:$D160,$D160)=1,MAX($L$4:L159)+1,"")) -> 127
A161: 46260 | B161: Purchase | C161: Birds Palace | D161: PO-WET-NB-KD-001 | E161: Nature Bridge Veterinary Exclusive Wet Cat Food for Kidney 190gm | F161: Cat Pouch | G161: 24 | H161: 290 | I161: =IF($B161="Return to Supplier",-G161*H161,G161*H161) -> 6960 | K161: =IF($B161="Return to Supplier",-G161,G161) -> 24 | L161: =IF($D161="","",IF(COUNTIF($D$5:$D161,$D161)=1,MAX($L$4:L160)+1,"")) -> 128
A162: 46260 | B162: Purchase | C162: Birds Palace | D162: PO-WET-NB-UR-001 | E162: Nature Bridge Veterinary Exclusive Wet Cat Food for Urinary Tract 190gm | F162: Cat Pouch | G162: 24 | H162: 290 | I162: =IF($B162="Return to Supplier",-G162*H162,G162*H162) -> 6960 | K162: =IF($B162="Return to Supplier",-G162,G162) -> 24 | L162: =IF($D162="","",IF(COUNTIF($D$5:$D162,$D162)=1,MAX($L$4:L161)+1,"")) -> 129
A163: 46260 | B163: Purchase | C163: Birds Palace | D163: FD-DRY-KT-H/P-1.5KG-001 | E163: Haisenpet Premium Kitten Dry Cat Food Chicken, Fish, Egg & Milk 1.2KG | F163: Cat Food | G163: 3 | H163: 500 | I163: =IF($B163="Return to Supplier",-G163*H163,G163*H163) -> 1500 | K163: =IF($B163="Return to Supplier",-G163,G163) -> 3 | L163: =IF($D163="","",IF(COUNTIF($D$5:$D163,$D163)=1,MAX($L$4:L162)+1,"")) -> 130
... A201: 46267 | B201: Purchase | C201: 3s Impex | D201: FD-DRY-BON-KT-0001 | E201: Bonacibo Super Premium Cat (Chicken, Rice with Anchovy) 1.5KG | F201: Cat Food | G201: 10 | H201: 800 | I201: =IF($B201="Return to Supplier",-G201*H201,G201*H201) -> 8000 | K201: =IF($B201="Return to Supplier",-G201,G201) -> 10 | L201: =IF($D201="","",IF(COUNTIF($D$5:$D201,$D201)=1,MAX($L$4:L200)+1,"")) -> 156
I202: =IF($B202="Return to Supplier",-G202*H202,G202*H202) -> 0 | K202: =IF($B202="Return to Supplier",-G202,G202) | L202: =IF($D202="","",IF(COUNTIF($D$5:$D202,$D202)=1,MAX($L$4:L201)+1,""))
I203: =IF($B203="Return to Supplier",-G203*H203,G203*H203) -> 0 | K203: =IF($B203="Return to Supplier",-G203,G203) | L203: =IF($D203="","",IF(COUNTIF($D$5:$D203,$D203)=1,MAX($L$4:L202)+1,""))
I204: =IF($B204="Return to Supplier",-G204*H204,G204*H204) -> 0 | K204: =IF($B204="Return to Supplier",-G204,G204) | L204: =IF($D204="","",IF(COUNTIF($D$5:$D204,$D204)=1,MAX($L$4:L203)+1,""))
I205: =IF($B205="Return to Supplier",-G205*H205,G205*H205) -> 0 | K205: =IF($B205="Return to Supplier",-G205,G205) | L205: =IF($D205="","",IF(COUNTIF($D$5:$D205,$D205)=1,MAX($L$4:L204)+1,""))
I206: =IF($B206="Return to Supplier",-G206*H206,G206*H206) -> 0 | K206: =IF($B206="Return to Supplier",-G206,G206) | L206: =IF($D206="","",IF(COUNTIF($D$5:$D206,$D206)=1,MAX($L$4:L205)+1,""))
I207: =IF($B207="Return to Supplier",-G207*H207,G207*H207) -> 0 | K207: =IF($B207="Return to Supplier",-G207,G207) | L207: =IF($D207="","",IF(COUNTIF($D$5:$D207,$D207)=1,MAX($L$4:L206)+1,""))
I208: =IF($B208="Return to Supplier",-G208*H208,G208*H208) -> 0 | K208: =IF($B208="Return to Supplier",-G208,G208) | L208: =IF($D208="","",IF(COUNTIF($D$5:$D208,$D208)=1,MAX($L$4:L207)+1,""))
I209: =IF($B209="Return to Supplier",-G209*H209,G209*H209) -> 0 | K209: =IF($B209="Return to Supplier",-G209,G209) | L209: =IF($D209="","",IF(COUNTIF($D$5:$D209,$D209)=1,MAX($L$4:L208)+1,""))
I210: =IF($B210="Return to Supplier",-G210*H210,G210*H210) -> 0 | K210: =IF($B210="Return to Supplier",-G210,G210) | L210: =IF($D210="","",IF(COUNTIF($D$5:$D210,$D210)=1,MAX($L$4:L209)+1,""))
I211: =IF($B211="Return to Supplier",-G211*H211,G211*H211) -> 0 | K211: =IF($B211="Return to Supplier",-G211,G211) | L211: =IF($D211="","",IF(COUNTIF($D$5:$D211,$D211)=1,MAX($L$4:L210)+1,""))
...

Sheet Inventory
A1: INVENTORY / STOCK TRACKER
A2: Auto-populates from Purchases — just add new purchase rows in Purchases and the product appears here automatically. Fill in MRP (yellow) for any new product. | O2: Items with no MRP set: | P2: {=SUMPRODUCT(--($A$5:$A$604<>""),--(($K$5:$K$604="")+($K$5:$K$604=0)>0))} -> 0
A3: TOTALS → | D3: =SUM(Inventory!$D$5:$D$604) -> 3031 | E3: =SUM(Inventory!$E$5:$E$604) -> 1005 | F3: =SUM(Inventory!$F$5:$F$604) -> 1 | H3: =SUM(Inventory!$H$5:$H$604) -> 1569 | J3: =SUM(Inventory!$J$5:$J$604) -> 204214.08 | O3: Codes fill in by themselves from Purchases — just type the price in any yellow cell.
A4: Item Code | B4: Product Description | C4: Category | D4: Purchased Qty | E4: Sold Qty | F4: Returned Qty | G4: Given to Shops (Qty) | H4: Current Stock | I4: Avg Unit Cost (Tk) | J4: Stock Value (Tk) | K4: MRP (Tk) | L4: Profit Margin % (of MRP) | M4: Profit Markup % (on Cost) | N4: (spacer) | O4: MRP Master — Item Code (auto-fills) | P4: MRP (Tk) — type price here
A5: {=IFERROR(INDEX(Purchases!$D$5:$D$1004,MATCH(ROW()-4,Purchases!$L$5:$L$1004,0)),"")} -> AC-PNC-LR-002 | B5: =IFERROR(VLOOKUP(A5,Purchases!$D:$E,2,FALSE),"") -> Pet Nail Clippers Large | C5: =IFERROR(VLOOKUP(A5,Purchases!$D:$F,3,FALSE),"") -> Cat Accessories | D5: =IF(A5="","",SUMIF(Purchases!$D:$D,A5,Purchases!$K:$K)) -> 1 | E5: =IF(A5="","",SUMIFS(Sales!$H:$H,Sales!$F:$F,A5,Sales!$B:$B,"<>Return")) -> 0 | F5: =IF(A5="","",SUMIFS(Sales!$H:$H,Sales!$F:$F,A5,Sales!$B:$B,"Return")) -> 0 | G5: =IF($A5="","",SUMIF('Shop Ledger'!$C:$C,$A5,'Shop Ledger'!$F:$F)) -> 0 | H5: =IF(A5="","",D5-E5+F5-G5) -> 1 | I5: =IF(A5="","",IFERROR(SUMIF(Purchases!$D:$D,A5,Purchases!$I:$I)/D5,0)) -> 190 | J5: =IF(A5="","",H5*I5) -> 190 | K5: =IF($A5="","",IFERROR(VALUE(SUBSTITUTE(SUBSTITUTE(SUBSTITUTE(VLOOKUP($A5,Inventory!$O$5:$P$604,2,FALSE),"Tk","")," ",""),",","")),"")) -> 270 | L5: =IF(OR(I5="",K5="",K5=0),"",(K5-I5)/K5) -> 0.2962963 | M5: =IF(OR(I5="",K5="",K5=0,I5=0),"",(K5-I5)/I5) -> 0.42105263 | O5: =IF($A5="","",$A5) -> AC-PNC-LR-002 | P5: 270
A6: {=IFERROR(INDEX(Purchases!$D$5:$D$1004,MATCH(ROW()-4,Purchases!$L$5:$L$1004,0)),"")} -> AC-CTOY-004 | B6: =IFERROR(VLOOKUP(A6,Purchases!$D:$E,2,FALSE),"") -> Cat Ball Robot Toy | C6: =IFERROR(VLOOKUP(A6,Purchases!$D:$F,3,FALSE),"") -> Cat Accessories | D6: =IF(A6="","",SUMIF(Purchases!$D:$D,A6,Purchases!$K:$K)) -> 1 | E6: =IF(A6="","",SUMIFS(Sales!$H:$H,Sales!$F:$F,A6,Sales!$B:$B,"<>Return")) -> 0 | F6: =IF(A6="","",SUMIFS(Sales!$H:$H,Sales!$F:$F,A6,Sales!$B:$B,"Return")) -> 0 | G6: =IF($A6="","",SUMIF('Shop Ledger'!$C:$C,$A6,'Shop Ledger'!$F:$F)) -> 0 | H6: =IF(A6="","",D6-E6+F6-G6) -> 1 | I6: =IF(A6="","",IFERROR(SUMIF(Purchases!$D:$D,A6,Purchases!$I:$I)/D6,0)) -> 95 | J6: =IF(A6="","",H6*I6) -> 95 | K6: =IF($A6="","",IFERROR(VALUE(SUBSTITUTE(SUBSTITUTE(SUBSTITUTE(VLOOKUP($A6,Inventory!$O$5:$P$604,2,FALSE),"Tk","")," ",""),",","")),"")) -> 150 | L6: =IF(OR(I6="",K6="",K6=0),"",(K6-I6)/K6) -> 0.36666667 | M6: =IF(OR(I6="",K6="",K6=0,I6=0),"",(K6-I6)/I6) -> 0.57894737 | O6: =IF($A6="","",$A6) -> AC-CTOY-004 | P6: 150
A7: {=IFERROR(INDEX(Purchases!$D$5:$D$1004,MATCH(ROW()-4,Purchases!$L$5:$L$1004,0)),"")} -> AC-CB-001 | B7: =IFERROR(VLOOKUP(A7,Purchases!$D:$E,2,FALSE),"") -> Cat Belt | C7: =IFERROR(VLOOKUP(A7,Purchases!$D:$F,3,FALSE),"") -> Cat Accessories | D7: =IF(A7="","",SUMIF(Purchases!$D:$D,A7,Purchases!$K:$K)) -> 37 | E7: =IF(A7="","",SUMIFS(Sales!$H:$H,Sales!$F:$F,A7,Sales!$B:$B,"<>Return")) -> 11 | F7: =IF(A7="","",SUMIFS(Sales!$H:$H,Sales!$F:$F,A7,Sales!$B:$B,"Return")) -> 0 | G7: =IF($A7="","",SUMIF('Shop Ledger'!$C:$C,$A7,'Shop Ledger'!$F:$F)) -> 0 | H7: =IF(A7="","",D7-E7+F7-G7) -> 26 | I7: =IF(A7="","",IFERROR(SUMIF(Purchases!$D:$D,A7,Purchases!$I:$I)/D7,0)) -> 29.351351 | J7: =IF(A7="","",H7*I7) -> 763.13514 | K7: =IF($A7="","",IFERROR(VALUE(SUBSTITUTE(SUBSTITUTE(SUBSTITUTE(VLOOKUP($A7,Inventory!$O$5:$P$604,2,FALSE),"Tk","")," ",""),",","")),"")) -> 60 | L7: =IF(OR(I7="",K7="",K7=0),"",(K7-I7)/K7) -> 0.51081081 | M7: =IF(OR(I7="",K7="",K7=0,I7=0),"",(K7-I7)/I7) -> 1.0441989 | O7: =IF($A7="","",$A7) -> AC-CB-001 | P7: 60
A8: {=IFERROR(INDEX(Purchases!$D$5:$D$1004,MATCH(ROW()-4,Purchases!$L$5:$L$1004,0)),"")} -> PO-WET-NK-70G-001 | B8: =IFERROR(VLOOKUP(A8,Purchases!$D:$E,2,FALSE),"") -> Nekko Pouch Tuna in Jelly | C8: =IFERROR(VLOOKUP(A8,Purchases!$D:$F,3,FALSE),"") -> Cat Pouch | D8: =IF(A8="","",SUMIF(Purchases!$D:$D,A8,Purchases!$K:$K)) -> 58 | E8: =IF(A8="","",SUMIFS(Sales!$H:$H,Sales!$F:$F,A8,Sales!$B:$B,"<>Return")) -> 11 | F8: =IF(A8="","",SUMIFS(Sales!$H:$H,Sales!$F:$F,A8,Sales!$B:$B,"Return")) -> 0 | G8: =IF($A8="","",SUMIF('Shop Ledger'!$C:$C,$A8,'Shop Ledger'!$F:$F)) -> 12 | H8: =IF(A8="","",D8-E8+F8-G8) -> 35 | I8: =IF(A8="","",IFERROR(SUMIF(Purchases!$D:$D,A8,Purchases!$I:$I)/D8,0)) -> 65.172414 | J8: =IF(A8="","",H8*I8) -> 2281.0345 | K8: =IF($A8="","",IFERROR(VALUE(SUBSTITUTE(SUBSTITUTE(SUBSTITUTE(VLOOKUP($A8,Inventory!$O$5:$P$604,2,FALSE),"Tk","")," ",""),",","")),"")) -> 90 | L8: =IF(OR(I8="",K8="",K8=0),"",(K8-I8)/K8) -> 0.27586207 | M8: =IF(OR(I8="",K8="",K8=0,I8=0),"",(K8-I8)/I8) -> 0.38095238 | O8: =IF($A8="","",$A8) -> PO-WET-NK-70G-001 | P8: 90
A9: {=IFERROR(INDEX(Purchases!$D$5:$D$1004,MATCH(ROW()-4,Purchases!$L$5:$L$1004,0)),"")} -> AC-CJ-AR-001 | B9: =IFERROR(VLOOKUP(A9,Purchases!$D:$E,2,FALSE),"") -> Cat Jersey Argentina Medium | C9: =IFERROR(VLOOKUP(A9,Purchases!$D:$F,3,FALSE),"") -> Cat Accessories | D9: =IF(A9="","",SUMIF(Purchases!$D:$D,A9,Purchases!$K:$K)) -> 3 | E9: =IF(A9="","",SUMIFS(Sales!$H:$H,Sales!$F:$F,A9,Sales!$B:$B,"<>Return")) -> 2 | F9: =IF(A9="","",SUMIFS(Sales!$H:$H,Sales!$F:$F,A9,Sales!$B:$B,"Return")) -> 0 | G9: =IF($A9="","",SUMIF('Shop Ledger'!$C:$C,$A9,'Shop Ledger'!$F:$F)) -> 0 | H9: =IF(A9="","",D9-E9+F9-G9) -> 1 | I9: =IF(A9="","",IFERROR(SUMIF(Purchases!$D:$D,A9,Purchases!$I:$I)/D9,0)) -> 140 | J9: =IF(A9="","",H9*I9) -> 140 | K9: =IF($A9="","",IFERROR(VALUE(SUBSTITUTE(SUBSTITUTE(SUBSTITUTE(VLOOKUP($A9,Inventory!$O$5:$P$604,2,FALSE),"Tk","")," ",""),",","")),"")) -> 300 | L9: =IF(OR(I9="",K9="",K9=0),"",(K9-I9)/K9) -> 0.53333333 | M9: =IF(OR(I9="",K9="",K9=0,I9=0),"",(K9-I9)/I9) -> 1.1428571 | O9: =IF($A9="","",$A9) -> AC-CJ-AR-001 | P9: 300
A10: {=IFERROR(INDEX(Purchases!$D$5:$D$1004,MATCH(ROW()-4,Purchases!$L$5:$L$1004,0)),"")} -> AC-CJ-AR-002 | B10: =IFERROR(VLOOKUP(A10,Purchases!$D:$E,2,FALSE),"") -> Cat Jersey Argentina Large | C10: =IFERROR(VLOOKUP(A10,Purchases!$D:$F,3,FALSE),"") -> Cat Accessories | D10: =IF(A10="","",SUMIF(Purchases!$D:$D,A10,Purchases!$K:$K)) -> 1 | E10: =IF(A10="","",SUMIFS(Sales!$H:$H,Sales!$F:$F,A10,Sales!$B:$B,"<>Return")) -> 1 | F10: =IF(A10="","",SUMIFS(Sales!$H:$H,Sales!$F:$F,A10,Sales!$B:$B,"Return")) -> 0 | G10: =IF($A10="","",SUMIF('Shop Ledger'!$C:$C,$A10,'Shop Ledger'!$F:$F)) -> 0 | H10: =IF(A10="","",D10-E10+F10-G10) -> 0 | I10: =IF(A10="","",IFERROR(SUMIF(Purchases!$D:$D,A10,Purchases!$I:$I)/D10,0)) -> 140 | J10: =IF(A10="","",H10*I10) -> 0 | K10: =IF($A10="","",IFERROR(VALUE(SUBSTITUTE(SUBSTITUTE(SUBSTITUTE(VLOOKUP($A10,Inventory!$O$5:$P$604,2,FALSE),"Tk","")," ",""),",","")),"")) -> 300 | L10: =IF(OR(I10="",K10="",K10=0),"",(K10-I10)/K10) -> 0.53333333 | M10: =IF(OR(I10="",K10="",K10=0,I10=0),"",(K10-I10)/I10) -> 1.1428571 | O10: =IF($A10="","",$A10) -> AC-CJ-AR-002 | P10: 300
A11: {=IFERROR(INDEX(Purchases!$D$5:$D$1004,MATCH(ROW()-4,Purchases!$L$5:$L$1004,0)),"")} -> AC-CJ-BR-002 | B11: =IFERROR(VLOOKUP(A11,Purchases!$D:$E,2,FALSE),"") -> Cat Jersey Brazil Large | C11: =IFERROR(VLOOKUP(A11,Purchases!$D:$F,3,FALSE),"") -> Cat Accessories | D11: =IF(A11="","",SUMIF(Purchases!$D:$D,A11,Purchases!$K:$K)) -> 2 | E11: =IF(A11="","",SUMIFS(Sales!$H:$H,Sales!$F:$F,A11,Sales!$B:$B,"<>Return")) -> 0 | F11: =IF(A11="","",SUMIFS(Sales!$H:$H,Sales!$F:$F,A11,Sales!$B:$B,"Return")) -> 0 | G11: =IF($A11="","",SUMIF('Shop Ledger'!$C:$C,$A11,'Shop Ledger'!$F:$F)) -> 0 | H11: =IF(A11="","",D11-E11+F11-G11) -> 2 | I11: =IF(A11="","",IFERROR(SUMIF(Purchases!$D:$D,A11,Purchases!$I:$I)/D11,0)) -> 140 | J11: =IF(A11="","",H11*I11) -> 280 | K11: =IF($A11="","",IFERROR(VALUE(SUBSTITUTE(SUBSTITUTE(SUBSTITUTE(VLOOKUP($A11,Inventory!$O$5:$P$604,2,FALSE),"Tk","")," ",""),",","")),"")) -> 300 | L11: =IF(OR(I11="",K11="",K11=0),"",(K11-I11)/K11) -> 0.53333333 | M11: =IF(OR(I11="",K11="",K11=0,I11=0),"",(K11-I11)/I11) -> 1.1428571 | O11: =IF($A11="","",$A11) -> AC-CJ-BR-002 | P11: 300
A12: {=IFERROR(INDEX(Purchases!$D$5:$D$1004,MATCH(ROW()-4,Purchases!$L$5:$L$1004,0)),"")} -> AC-CJ-BR-001 | B12: =IFERROR(VLOOKUP(A12,Purchases!$D:$E,2,FALSE),"") -> Cat Jersey Brazil Medium | C12: =IFERROR(VLOOKUP(A12,Purchases!$D:$F,3,FALSE),"") -> Cat Accessories | D12: =IF(A12="","",SUMIF(Purchases!$D:$D,A12,Purchases!$K:$K)) -> 3 | E12: =IF(A12="","",SUMIFS(Sales!$H:$H,Sales!$F:$F,A12,Sales!$B:$B,"<>Return")) -> 0 | F12: =IF(A12="","",SUMIFS(Sales!$H:$H,Sales!$F:$F,A12,Sales!$B:$B,"Return")) -> 0 | G12: =IF($A12="","",SUMIF('Shop Ledger'!$C:$C,$A12,'Shop Ledger'!$F:$F)) -> 0 | H12: =IF(A12="","",D12-E12+F12-G12) -> 3 | I12: =IF(A12="","",IFERROR(SUMIF(Purchases!$D:$D,A12,Purchases!$I:$I)/D12,0)) -> 140 | J12: =IF(A12="","",H12*I12) -> 420 | K12: =IF($A12="","",IFERROR(VALUE(SUBSTITUTE(SUBSTITUTE(SUBSTITUTE(VLOOKUP($A12,Inventory!$O$5:$P$604,2,FALSE),"Tk","")," ",""),",","")),"")) -> 300 | L12: =IF(OR(I12="",K12="",K12=0),"",(K12-I12)/K12) -> 0.53333333 | M12: =IF(OR(I12="",K12="",K12=0,I12=0),"",(K12-I12)/I12) -> 1.1428571 | O12: =IF($A12="","",$A12) -> AC-CJ-BR-001 | P12: 300
A13: {=IFERROR(INDEX(Purchases!$D$5:$D$1004,MATCH(ROW()-4,Purchases!$L$5:$L$1004,0)),"")} -> AC-SHAMP-002 | B13: =IFERROR(VLOOKUP(A13,Purchases!$D:$E,2,FALSE),"") -> Bengal Flea & Tick Shampoo | C13: =IFERROR(VLOOKUP(A13,Purchases!$D:$F,3,FALSE),"") -> Cat Accessories | D13: =IF(A13="","",SUMIF(Purchases!$D:$D,A13,Purchases!$K:$K)) -> 9 | E13: =IF(A13="","",SUMIFS(Sales!$H:$H,Sales!$F:$F,A13,Sales!$B:$B,"<>Return")) -> 6 | F13: =IF(A13="","",SUMIFS(Sales!$H:$H,Sales!$F:$F,A13,Sales!$B:$B,"Return")) -> 0 | G13: =IF($A13="","",SUMIF('Shop Ledger'!$C:$C,$A13,'Shop Ledger'!$F:$F)) -> 1 | H13: =IF(A13="","",D13-E13+F13-G13) -> 2 | I13: =IF(A13="","",IFERROR(SUMIF(Purchases!$D:$D,A13,Purchases!$I:$I)/D13,0)) -> 240 | J13: =IF(A13="","",H13*I13) -> 480 | K13: =IF($A13="","",IFERROR(VALUE(SUBSTITUTE(SUBSTITUTE(SUBSTITUTE(VLOOKUP($A13,Inventory!$O$5:$P$604,2,FALSE),"Tk","")," ",""),",","")),"")) -> 400 | L13: =IF(OR(I13="",K13="",K13=0),"",(K13-I13)/K13) -> 0.4 | M13: =IF(OR(I13="",K13="",K13=0,I13=0),"",(K13-I13)/I13) -> 0.66666667 | O13: =IF($A13="","",$A13) -> AC-SHAMP-002 | P13: 400
A14: {=IFERROR(INDEX(Purchases!$D$5:$D$1004,MATCH(ROW()-4,Purchases!$L$5:$L$1004,0)),"")} -> AC-SHAMP-003 | B14: =IFERROR(VLOOKUP(A14,Purchases!$D:$E,2,FALSE),"") -> Bengal Waterless Bath No-Rinse Shampoo | C14: =IFERROR(VLOOKUP(A14,Purchases!$D:$F,3,FALSE),"") -> Cat Accessories | D14: =IF(A14="","",SUMIF(Purchases!$D:$D,A14,Purchases!$K:$K)) -> 1 | E14: =IF(A14="","",SUMIFS(Sales!$H:$H,Sales!$F:$F,A14,Sales!$B:$B,"<>Return")) -> 0 | F14: =IF(A14="","",SUMIFS(Sales!$H:$H,Sales!$F:$F,A14,Sales!$B:$B,"Return")) -> 0 | G14: =IF($A14="","",SUMIF('Shop Ledger'!$C:$C,$A14,'Shop Ledger'!$F:$F)) -> 0 | H14: =IF(A14="","",D14-E14+F14-G14) -> 1 | I14: =IF(A14="","",IFERROR(SUMIF(Purchases!$D:$D,A14,Purchases!$I:$I)/D14,0)) -> 290 | J14: =IF(A14="","",H14*I14) -> 290 | K14: =IF($A14="","",IFERROR(VALUE(SUBSTITUTE(SUBSTITUTE(SUBSTITUTE(VLOOKUP($A14,Inventory!$O$5:$P$604,2,FALSE),"Tk","")," ",""),",","")),"")) -> 450 | L14: =IF(OR(I14="",K14="",K14=0),"",(K14-I14)/K14) -> 0.35555556 | M14: =IF(OR(I14="",K14="",K14=0,I14=0),"",(K14-I14)/I14) -> 0.55172414 | O14: =IF($A14="","",$A14) -> AC-SHAMP-003 | P14: 450
A15: {=IFERROR(INDEX(Purchases!$D$5:$D$1004,MATCH(ROW()-4,Purchases!$L$5:$L$1004,0)),"")} -> AC-LB-001 | B15: =IFERROR(VLOOKUP(A15,Purchases!$D:$E,2,FALSE),"") -> Cat Litter Box Large | C15: =IFERROR(VLOOKUP(A15,Purchases!$D:$F,3,FALSE),"") -> Cat Accessories | D15: =IF(A15="","",SUMIF(Purchases!$D:$D,A15,Purchases!$K:$K)) -> 1 | E15: =IF(A15="","",SUMIFS(Sales!$H:$H,Sales!$F:$F,A15,Sales!$B:$B,"<>Return")) -> 1 | F15: =IF(A15="","",SUMIFS(Sales!$H:$H,Sales!$F:$F,A15,Sales!$B:$B,"Return")) -> 0 | G15: =IF($A15="","",SUMIF('Shop Ledger'!$C:$C,$A15,'Shop Ledger'!$F:$F)) -> 0 | H15: =IF(A15="","",D15-E15+F15-G15) -> 0 | I15: =IF(A15="","",IFERROR(SUMIF(Purchases!$D:$D,A15,Purchases!$I:$I)/D15,0)) -> 400 | J15: =IF(A15="","",H15*I15) -> 0 | K15: =IF($A15="","",IFERROR(VALUE(SUBSTITUTE(SUBSTITUTE(SUBSTITUTE(VLOOKUP($A15,Inventory!$O$5:$P$604,2,FALSE),"Tk","")," ",""),",","")),"")) -> 600 | L15: =IF(OR(I15="",K15="",K15=0),"",(K15-I15)/K15) -> 0.33333333 | M15: =IF(OR(I15="",K15="",K15=0,I15=0),"",(K15-I15)/I15) -> 0.5 | O15: =IF($A15="","",$A15) -> AC-LB-001 | P15: 600
A16: {=IFERROR(INDEX(Purchases!$D$5:$D$1004,MATCH(ROW()-4,Purchases!$L$5:$L$1004,0)),"")} -> AC-LB-002 | B16: =IFERROR(VLOOKUP(A16,Purchases!$D:$E,2,FALSE),"") -> Cat Litter Box Medium | C16: =IFERROR(VLOOKUP(A16,Purchases!$D:$F,3,FALSE),"") -> Cat Accessories | D16: =IF(A16="","",SUMIF(Purchases!$D:$D,A16,Purchases!$K:$K)) -> 6 | E16: =IF(A16="","",SUMIFS(Sales!$H:$H,Sales!$F:$F,A16,Sales!$B:$B,"<>Return")) -> 4 | F16: =IF(A16="","",SUMIFS(Sales!$H:$H,Sales!$F:$F,A16,Sales!$B:$B,"Return")) -> 0 | G16: =IF($A16="","",SUMIF('Shop Ledger'!$C:$C,$A16,'Shop Ledger'!$F:$F)) -> 0 | H16: =IF(A16="","",D16-E16+F16-G16) -> 2 | I16: =IF(A16="","",IFERROR(SUMIF(Purchases!$D:$D,A16,Purchases!$I:$I)/D16,0)) -> 300 | J16: =IF(A16="","",H16*I16) -> 600 | K16: =IF($A16="","",IFERROR(VALUE(SUBSTITUTE(SUBSTITUTE(SUBSTITUTE(VLOOKUP($A16,Inventory!$O$5:$P$604,2,FALSE),"Tk","")," ",""),",","")),"")) -> 500 | L16: =IF(OR(I16="",K16="",K16=0),"",(K16-I16)/K16) -> 0.4 | M16: =IF(OR(I16="",K16="",K16=0,I16=0),"",(K16-I16)/I16) -> 0.66666667 | O16: =IF($A16="","",$A16) -> AC-LB-002 | P16: 500
... A160: {=IFERROR(INDEX(Purchases!$D$5:$D$1004,MATCH(ROW()-4,Purchases!$L$5:$L$1004,0)),"")} -> FD-DRY-BON-KT-0001 | B160: =IFERROR(VLOOKUP(A160,Purchases!$D:$E,2,FALSE),"") -> Bonacibo Super Premium Cat (Chicken, Rice with Anchovy) 1.5KG | C160: =IFERROR(VLOOKUP(A160,Purchases!$D:$F,3,FALSE),"") -> Cat Food | D160: =IF(A160="","",SUMIF(Purchases!$D:$D,A160,Purchases!$K:$K)) -> 10 | E160: =IF(A160="","",SUMIFS(Sales!$H:$H,Sales!$F:$F,A160,Sales!$B:$B,"<>Return")) -> 0 | F160: =IF(A160="","",SUMIFS(Sales!$H:$H,Sales!$F:$F,A160,Sales!$B:$B,"Return")) -> 0 | G160: =IF($A160="","",SUMIF('Shop Ledger'!$C:$C,$A160,'Shop Ledger'!$F:$F)) -> 0 | H160: =IF(A160="","",D160-E160+F160-G160) -> 10 | I160: =IF(A160="","",IFERROR(SUMIF(Purchases!$D:$D,A160,Purchases!$I:$I)/D160,0)) -> 800 | J160: =IF(A160="","",H160*I160) -> 8000 | K160: =IF($A160="","",IFERROR(VALUE(SUBSTITUTE(SUBSTITUTE(SUBSTITUTE(VLOOKUP($A160,Inventory!$O$5:$P$604,2,FALSE),"Tk","")," ",""),",","")),"")) -> 1050 | L160: =IF(OR(I160="",K160="",K160=0),"",(K160-I160)/K160) -> 0.23809524 | M160: =IF(OR(I160="",K160="",K160=0,I160=0),"",(K160-I160)/I160) -> 0.3125 | O160: =IF($A160="","",$A160) -> FD-DRY-BON-KT-0001 | P160: 1050
A161: {=IFERROR(INDEX(Purchases!$D$5:$D$1004,MATCH(ROW()-4,Purchases!$L$5:$L$1004,0)),"")} | B161: =IFERROR(VLOOKUP(A161,Purchases!$D:$E,2,FALSE),"") | C161: =IFERROR(VLOOKUP(A161,Purchases!$D:$F,3,FALSE),"") | D161: =IF(A161="","",SUMIF(Purchases!$D:$D,A161,Purchases!$K:$K)) | E161: =IF(A161="","",SUMIFS(Sales!$H:$H,Sales!$F:$F,A161,Sales!$B:$B,"<>Return")) | F161: =IF(A161="","",SUMIFS(Sales!$H:$H,Sales!$F:$F,A161,Sales!$B:$B,"Return")) | G161: =IF($A161="","",SUMIF('Shop Ledger'!$C:$C,$A161,'Shop Ledger'!$F:$F)) | H161: =IF(A161="","",D161-E161+F161-G161) | I161: =IF(A161="","",IFERROR(SUMIF(Purchases!$D:$D,A161,Purchases!$I:$I)/D161,0)) | J161: =IF(A161="","",H161*I161) | K161: =IF($A161="","",IFERROR(VALUE(SUBSTITUTE(SUBSTITUTE(SUBSTITUTE(VLOOKUP($A161,Inventory!$O$5:$P$604,2,FALSE),"Tk","")," ",""),",","")),"")) | L161: =IF(OR(I161="",K161="",K161=0),"",(K161-I161)/K161) | M161: =IF(OR(I161="",K161="",K161=0,I161=0),"",(K161-I161)/I161) | O161: =IF($A161="","",$A161)
A162: {=IFERROR(INDEX(Purchases!$D$5:$D$1004,MATCH(ROW()-4,Purchases!$L$5:$L$1004,0)),"")} | B162: =IFERROR(VLOOKUP(A162,Purchases!$D:$E,2,FALSE),"") | C162: =IFERROR(VLOOKUP(A162,Purchases!$D:$F,3,FALSE),"") | D162: =IF(A162="","",SUMIF(Purchases!$D:$D,A162,Purchases!$K:$K)) | E162: =IF(A162="","",SUMIFS(Sales!$H:$H,Sales!$F:$F,A162,Sales!$B:$B,"<>Return")) | F162: =IF(A162="","",SUMIFS(Sales!$H:$H,Sales!$F:$F,A162,Sales!$B:$B,"Return")) | G162: =IF($A162="","",SUMIF('Shop Ledger'!$C:$C,$A162,'Shop Ledger'!$F:$F)) | H162: =IF(A162="","",D162-E162+F162-G162) | I162: =IF(A162="","",IFERROR(SUMIF(Purchases!$D:$D,A162,Purchases!$I:$I)/D162,0)) | J162: =IF(A162="","",H162*I162) | K162: =IF($A162="","",IFERROR(VALUE(SUBSTITUTE(SUBSTITUTE(SUBSTITUTE(VLOOKUP($A162,Inventory!$O$5:$P$604,2,FALSE),"Tk","")," ",""),",","")),"")) | L162: =IF(OR(I162="",K162="",K162=0),"",(K162-I162)/K162) | M162: =IF(OR(I162="",K162="",K162=0,I162=0),"",(K162-I162)/I162) | O162: =IF($A162="","",$A162)
A163: {=IFERROR(INDEX(Purchases!$D$5:$D$1004,MATCH(ROW()-4,Purchases!$L$5:$L$1004,0)),"")} | B163: =IFERROR(VLOOKUP(A163,Purchases!$D:$E,2,FALSE),"") | C163: =IFERROR(VLOOKUP(A163,Purchases!$D:$F,3,FALSE),"") | D163: =IF(A163="","",SUMIF(Purchases!$D:$D,A163,Purchases!$K:$K)) | E163: =IF(A163="","",SUMIFS(Sales!$H:$H,Sales!$F:$F,A163,Sales!$B:$B,"<>Return")) | F163: =IF(A163="","",SUMIFS(Sales!$H:$H,Sales!$F:$F,A163,Sales!$B:$B,"Return")) | G163: =IF($A163="","",SUMIF('Shop Ledger'!$C:$C,$A163,'Shop Ledger'!$F:$F)) | H163: =IF(A163="","",D163-E163+F163-G163) | I163: =IF(A163="","",IFERROR(SUMIF(Purchases!$D:$D,A163,Purchases!$I:$I)/D163,0)) | J163: =IF(A163="","",H163*I163) | K163: =IF($A163="","",IFERROR(VALUE(SUBSTITUTE(SUBSTITUTE(SUBSTITUTE(VLOOKUP($A163,Inventory!$O$5:$P$604,2,FALSE),"Tk","")," ",""),",","")),"")) | L163: =IF(OR(I163="",K163="",K163=0),"",(K163-I163)/K163) | M163: =IF(OR(I163="",K163="",K163=0,I163=0),"",(K163-I163)/I163) | O163: =IF($A163="","",$A163)
A164: {=IFERROR(INDEX(Purchases!$D$5:$D$1004,MATCH(ROW()-4,Purchases!$L$5:$L$1004,0)),"")} | B164: =IFERROR(VLOOKUP(A164,Purchases!$D:$E,2,FALSE),"") | C164: =IFERROR(VLOOKUP(A164,Purchases!$D:$F,3,FALSE),"") | D164: =IF(A164="","",SUMIF(Purchases!$D:$D,A164,Purchases!$K:$K)) | E164: =IF(A164="","",SUMIFS(Sales!$H:$H,Sales!$F:$F,A164,Sales!$B:$B,"<>Return")) | F164: =IF(A164="","",SUMIFS(Sales!$H:$H,Sales!$F:$F,A164,Sales!$B:$B,"Return")) | G164: =IF($A164="","",SUMIF('Shop Ledger'!$C:$C,$A164,'Shop Ledger'!$F:$F)) | H164: =IF(A164="","",D164-E164+F164-G164) | I164: =IF(A164="","",IFERROR(SUMIF(Purchases!$D:$D,A164,Purchases!$I:$I)/D164,0)) | J164: =IF(A164="","",H164*I164) | K164: =IF($A164="","",IFERROR(VALUE(SUBSTITUTE(SUBSTITUTE(SUBSTITUTE(VLOOKUP($A164,Inventory!$O$5:$P$604,2,FALSE),"Tk","")," ",""),",","")),"")) | L164: =IF(OR(I164="",K164="",K164=0),"",(K164-I164)/K164) | M164: =IF(OR(I164="",K164="",K164=0,I164=0),"",(K164-I164)/I164) | O164: =IF($A164="","",$A164)
A165: {=IFERROR(INDEX(Purchases!$D$5:$D$1004,MATCH(ROW()-4,Purchases!$L$5:$L$1004,0)),"")} | B165: =IFERROR(VLOOKUP(A165,Purchases!$D:$E,2,FALSE),"") | C165: =IFERROR(VLOOKUP(A165,Purchases!$D:$F,3,FALSE),"") | D165: =IF(A165="","",SUMIF(Purchases!$D:$D,A165,Purchases!$K:$K)) | E165: =IF(A165="","",SUMIFS(Sales!$H:$H,Sales!$F:$F,A165,Sales!$B:$B,"<>Return")) | F165: =IF(A165="","",SUMIFS(Sales!$H:$H,Sales!$F:$F,A165,Sales!$B:$B,"Return")) | G165: =IF($A165="","",SUMIF('Shop Ledger'!$C:$C,$A165,'Shop Ledger'!$F:$F)) | H165: =IF(A165="","",D165-E165+F165-G165) | I165: =IF(A165="","",IFERROR(SUMIF(Purchases!$D:$D,A165,Purchases!$I:$I)/D165,0)) | J165: =IF(A165="","",H165*I165) | K165: =IF($A165="","",IFERROR(VALUE(SUBSTITUTE(SUBSTITUTE(SUBSTITUTE(VLOOKUP($A165,Inventory!$O$5:$P$604,2,FALSE),"Tk","")," ",""),",","")),"")) | L165: =IF(OR(I165="",K165="",K165=0),"",(K165-I165)/K165) | M165: =IF(OR(I165="",K165="",K165=0,I165=0),"",(K165-I165)/I165) | O165: =IF($A165="","",$A165)
A166: {=IFERROR(INDEX(Purchases!$D$5:$D$1004,MATCH(ROW()-4,Purchases!$L$5:$L$1004,0)),"")} | B166: =IFERROR(VLOOKUP(A166,Purchases!$D:$E,2,FALSE),"") | C166: =IFERROR(VLOOKUP(A166,Purchases!$D:$F,3,FALSE),"") | D166: =IF(A166="","",SUMIF(Purchases!$D:$D,A166,Purchases!$K:$K)) | E166: =IF(A166="","",SUMIFS(Sales!$H:$H,Sales!$F:$F,A166,Sales!$B:$B,"<>Return")) | F166: =IF(A166="","",SUMIFS(Sales!$H:$H,Sales!$F:$F,A166,Sales!$B:$B,"Return")) | G166: =IF($A166="","",SUMIF('Shop Ledger'!$C:$C,$A166,'Shop Ledger'!$F:$F)) | H166: =IF(A166="","",D166-E166+F166-G166) | I166: =IF(A166="","",IFERROR(SUMIF(Purchases!$D:$D,A166,Purchases!$I:$I)/D166,0)) | J166: =IF(A166="","",H166*I166) | K166: =IF($A166="","",IFERROR(VALUE(SUBSTITUTE(SUBSTITUTE(SUBSTITUTE(VLOOKUP($A166,Inventory!$O$5:$P$604,2,FALSE),"Tk","")," ",""),",","")),"")) | L166: =IF(OR(I166="",K166="",K166=0),"",(K166-I166)/K166) | M166: =IF(OR(I166="",K166="",K166=0,I166=0),"",(K166-I166)/I166) | O166: =IF($A166="","",$A166)
A167: {=IFERROR(INDEX(Purchases!$D$5:$D$1004,MATCH(ROW()-4,Purchases!$L$5:$L$1004,0)),"")} | B167: =IFERROR(VLOOKUP(A167,Purchases!$D:$E,2,FALSE),"") | C167: =IFERROR(VLOOKUP(A167,Purchases!$D:$F,3,FALSE),"") | D167: =IF(A167="","",SUMIF(Purchases!$D:$D,A167,Purchases!$K:$K)) | E167: =IF(A167="","",SUMIFS(Sales!$H:$H,Sales!$F:$F,A167,Sales!$B:$B,"<>Return")) | F167: =IF(A167="","",SUMIFS(Sales!$H:$H,Sales!$F:$F,A167,Sales!$B:$B,"Return")) | G167: =IF($A167="","",SUMIF('Shop Ledger'!$C:$C,$A167,'Shop Ledger'!$F:$F)) | H167: =IF(A167="","",D167-E167+F167-G167) | I167: =IF(A167="","",IFERROR(SUMIF(Purchases!$D:$D,A167,Purchases!$I:$I)/D167,0)) | J167: =IF(A167="","",H167*I167) | K167: =IF($A167="","",IFERROR(VALUE(SUBSTITUTE(SUBSTITUTE(SUBSTITUTE(VLOOKUP($A167,Inventory!$O$5:$P$604,2,FALSE),"Tk","")," ",""),",","")),"")) | L167: =IF(OR(I167="",K167="",K167=0),"",(K167-I167)/K167) | M167: =IF(OR(I167="",K167="",K167=0,I167=0),"",(K167-I167)/I167) | O167: =IF($A167="","",$A167)
A168: {=IFERROR(INDEX(Purchases!$D$5:$D$1004,MATCH(ROW()-4,Purchases!$L$5:$L$1004,0)),"")} | B168: =IFERROR(VLOOKUP(A168,Purchases!$D:$E,2,FALSE),"") | C168: =IFERROR(VLOOKUP(A168,Purchases!$D:$F,3,FALSE),"") | D168: =IF(A168="","",SUMIF(Purchases!$D:$D,A168,Purchases!$K:$K)) | E168: =IF(A168="","",SUMIFS(Sales!$H:$H,Sales!$F:$F,A168,Sales!$B:$B,"<>Return")) | F168: =IF(A168="","",SUMIFS(Sales!$H:$H,Sales!$F:$F,A168,Sales!$B:$B,"Return")) | G168: =IF($A168="","",SUMIF('Shop Ledger'!$C:$C,$A168,'Shop Ledger'!$F:$F)) | H168: =IF(A168="","",D168-E168+F168-G168) | I168: =IF(A168="","",IFERROR(SUMIF(Purchases!$D:$D,A168,Purchases!$I:$I)/D168,0)) | J168: =IF(A168="","",H168*I168) | K168: =IF($A168="","",IFERROR(VALUE(SUBSTITUTE(SUBSTITUTE(SUBSTITUTE(VLOOKUP($A168,Inventory!$O$5:$P$604,2,FALSE),"Tk","")," ",""),",","")),"")) | L168: =IF(OR(I168="",K168="",K168=0),"",(K168-I168)/K168) | M168: =IF(OR(I168="",K168="",K168=0,I168=0),"",(K168-I168)/I168) | O168: =IF($A168="","",$A168)
A169: {=IFERROR(INDEX(Purchases!$D$5:$D$1004,MATCH(ROW()-4,Purchases!$L$5:$L$1004,0)),"")} | B169: =IFERROR(VLOOKUP(A169,Purchases!$D:$E,2,FALSE),"") | C169: =IFERROR(VLOOKUP(A169,Purchases!$D:$F,3,FALSE),"") | D169: =IF(A169="","",SUMIF(Purchases!$D:$D,A169,Purchases!$K:$K)) | E169: =IF(A169="","",SUMIFS(Sales!$H:$H,Sales!$F:$F,A169,Sales!$B:$B,"<>Return")) | F169: =IF(A169="","",SUMIFS(Sales!$H:$H,Sales!$F:$F,A169,Sales!$B:$B,"Return")) | G169: =IF($A169="","",SUMIF('Shop Ledger'!$C:$C,$A169,'Shop Ledger'!$F:$F)) | H169: =IF(A169="","",D169-E169+F169-G169) | I169: =IF(A169="","",IFERROR(SUMIF(Purchases!$D:$D,A169,Purchases!$I:$I)/D169,0)) | J169: =IF(A169="","",H169*I169) | K169: =IF($A169="","",IFERROR(VALUE(SUBSTITUTE(SUBSTITUTE(SUBSTITUTE(VLOOKUP($A169,Inventory!$O$5:$P$604,2,FALSE),"Tk","")," ",""),",","")),"")) | L169: =IF(OR(I169="",K169="",K169=0),"",(K169-I169)/K169) | M169: =IF(OR(I169="",K169="",K169=0,I169=0),"",(K169-I169)/I169) | O169: =IF($A169="","",$A169)
A170: {=IFERROR(INDEX(Purchases!$D$5:$D$1004,MATCH(ROW()-4,Purchases!$L$5:$L$1004,0)),"")} | B170: =IFERROR(VLOOKUP(A170,Purchases!$D:$E,2,FALSE),"") | C170: =IFERROR(VLOOKUP(A170,Purchases!$D:$F,3,FALSE),"") | D170: =IF(A170="","",SUMIF(Purchases!$D:$D,A170,Purchases!$K:$K)) | E170: =IF(A170="","",SUMIFS(Sales!$H:$H,Sales!$F:$F,A170,Sales!$B:$B,"<>Return")) | F170: =IF(A170="","",SUMIFS(Sales!$H:$H,Sales!$F:$F,A170,Sales!$B:$B,"Return")) | G170: =IF($A170="","",SUMIF('Shop Ledger'!$C:$C,$A170,'Shop Ledger'!$F:$F)) | H170: =IF(A170="","",D170-E170+F170-G170) | I170: =IF(A170="","",IFERROR(SUMIF(Purchases!$D:$D,A170,Purchases!$I:$I)/D170,0)) | J170: =IF(A170="","",H170*I170) | K170: =IF($A170="","",IFERROR(VALUE(SUBSTITUTE(SUBSTITUTE(SUBSTITUTE(VLOOKUP($A170,Inventory!$O$5:$P$604,2,FALSE),"Tk","")," ",""),",","")),"")) | L170: =IF(OR(I170="",K170="",K170=0),"",(K170-I170)/K170) | M170: =IF(OR(I170="",K170="",K170=0,I170=0),"",(K170-I170)/I170) | O170: =IF($A170="","",$A170)
A171: {=IFERROR(INDEX(Purchases!$D$5:$D$1004,MATCH(ROW()-4,Purchases!$L$5:$L$1004,0)),"")} | B171: =IFERROR(VLOOKUP(A171,Purchases!$D:$E,2,FALSE),"") | C171: =IFERROR(VLOOKUP(A171,Purchases!$D:$F,3,FALSE),"") | D171: =IF(A171="","",SUMIF(Purchases!$D:$D,A171,Purchases!$K:$K)) | E171: =IF(A171="","",SUMIFS(Sales!$H:$H,Sales!$F:$F,A171,Sales!$B:$B,"<>Return")) | F171: =IF(A171="","",SUMIFS(Sales!$H:$H,Sales!$F:$F,A171,Sales!$B:$B,"Return")) | G171: =IF($A171="","",SUMIF('Shop Ledger'!$C:$C,$A171,'Shop Ledger'!$F:$F)) | H171: =IF(A171="","",D171-E171+F171-G171) | I171: =IF(A171="","",IFERROR(SUMIF(Purchases!$D:$D,A171,Purchases!$I:$I)/D171,0)) | J171: =IF(A171="","",H171*I171) | K171: =IF($A171="","",IFERROR(VALUE(SUBSTITUTE(SUBSTITUTE(SUBSTITUTE(VLOOKUP($A171,Inventory!$O$5:$P$604,2,FALSE),"Tk","")," ",""),",","")),"")) | L171: =IF(OR(I171="",K171="",K171=0),"",(K171-I171)/K171) | M171: =IF(OR(I171="",K171="",K171=0,I171=0),"",(K171-I171)/I171) | O171: =IF($A171="","",$A171)
A172: {=IFERROR(INDEX(Purchases!$D$5:$D$1004,MATCH(ROW()-4,Purchases!$L$5:$L$1004,0)),"")} | B172: =IFERROR(VLOOKUP(A172,Purchases!$D:$E,2,FALSE),"") | C172: =IFERROR(VLOOKUP(A172,Purchases!$D:$F,3,FALSE),"") | D172: =IF(A172="","",SUMIF(Purchases!$D:$D,A172,Purchases!$K:$K)) | E172: =IF(A172="","",SUMIFS(Sales!$H:$H,Sales!$F:$F,A172,Sales!$B:$B,"<>Return")) | F172: =IF(A172="","",SUMIFS(Sales!$H:$H,Sales!$F:$F,A172,Sales!$B:$B,"Return")) | G172: =IF($A172="","",SUMIF('Shop Ledger'!$C:$C,$A172,'Shop Ledger'!$F:$F)) | H172: =IF(A172="","",D172-E172+F172-G172) | I172: =IF(A172="","",IFERROR(SUMIF(Purchases!$D:$D,A172,Purchases!$I:$I)/D172,0)) | J172: =IF(A172="","",H172*I172) | K172: =IF($A172="","",IFERROR(VALUE(SUBSTITUTE(SUBSTITUTE(SUBSTITUTE(VLOOKUP($A172,Inventory!$O$5:$P$604,2,FALSE),"Tk","")," ",""),",","")),"")) | L172: =IF(OR(I172="",K172="",K172=0),"",(K172-I172)/K172) | M172: =IF(OR(I172="",K172="",K172=0,I172=0),"",(K172-I172)/I172) | O172: =IF($A172="","",$A172)
... A604: {=IFERROR(INDEX(Purchases!$D$5:$D$1004,MATCH(ROW()-4,Purchases!$L$5:$L$1004,0)),"")} | B604: =IFERROR(VLOOKUP(A604,Purchases!$D:$E,2,FALSE),"") | C604: =IFERROR(VLOOKUP(A604,Purchases!$D:$F,3,FALSE),"") | D604: =IF(A604="","",SUMIF(Purchases!$D:$D,A604,Purchases!$K:$K)) | E604: =IF(A604="","",SUMIFS(Sales!$H:$H,Sales!$F:$F,A604,Sales!$B:$B,"<>Return")) | F604: =IF(A604="","",SUMIFS(Sales!$H:$H,Sales!$F:$F,A604,Sales!$B:$B,"Return")) | G604: =IF($A604="","",SUMIF('Shop Ledger'!$C:$C,$A604,'Shop Ledger'!$F:$F)) | H604: =IF(A604="","",D604-E604+F604-G604) | I604: =IF(A604="","",IFERROR(SUMIF(Purchases!$D:$D,A604,Purchases!$I:$I)/D604,0)) | J604: =IF(A604="","",H604*I604) | K604: =IF($A604="","",IFERROR(VALUE(SUBSTITUTE(SUBSTITUTE(SUBSTITUTE(VLOOKUP($A604,Inventory!$O$5:$P$604,2,FALSE),"Tk","")," ",""),",","")),"")) | L604: =IF(OR(I604="",K604="",K604=0),"",(K604-I604)/K604) | M604: =IF(OR(I604="",K604="",K604=0,I604=0),"",(K604-I604)/I604) | O604: =IF($A604="","",$A604)

Sheet Sales
A1: SALES LOG | K1: SALES SUMMARY | AC1: TEST 1 - typed list -> click AD1 | AF1: ALPHA | AG1: =IF(AF1="","",AF1) -> ALPHA
A2: Enter each sale or return here. Type = "Sale" or "Return". Description, Unit Cost, Total Cost & Profit auto-calculate. | K2: Total Sales | L2: =SUM(Sales!$L$7:$L$1506) -> 147710.01 | M2: Cost of Goods | N2: =SUM(Sales!$O$7:$O$1506) -> 114725.88 | O2: Product Profit | P2: =SUM(Sales!$P$7:$P$1506) -> 32984.131 | AC2: TEST 2 - static range -> click AD2 | AF2: BRAVO | AG2: =IF(AF2="","",AF2) -> BRAVO
K3: Delivery Charged | L3: =SUM(Sales!$R$7:$R$1506) -> 1890 | M3: Delivery You Paid | N3: =SUM(Sales!$S$7:$S$1506) -> 1995 | O3: REAL Profit | P3: =SUM(Sales!$T$7:$T$1506) -> 32731.095 | AC3: TEST 3 - formula range -> click AD3 | AF3: CHARLIE | AG3: =IF(AF3="","",AF3) -> CHARLIE
K4: Total Due | L4: =SUMIFS(Sales!$L$7:$L$1506,Sales!$M$7:$M$1506,"Due") -> 6812.004 | M4: Profit Collected | N4: =SUMIFS(Sales!$T$7:$T$1506,Sales!$M$7:$M$1506,"Paid") -> 30785.757 | O4: Profit Pending | P4: =SUMIFS(Sales!$T$7:$T$1506,Sales!$M$7:$M$1506,"Due") -> 1544.8463
A6: Date | B6: Type | C6: Channel | D6: Customer | E6: Invoice Number | F6: Item Code (click here ↓ for dropdown) | G6: Product Description (auto-fills) | H6: Qty | I6: Unit Price (Tk) | J6: MRP (Tk) | K6: Discount (Tk) | L6: Total Amount (Tk) | M6: Payment Status | N6: Unit Cost (Tk) | O6: Total Cost (Tk) | P6: Profit (Tk) | Q6: Notes | R6: Delivery Charged to Customer (auto from Orders) | S6: Delivery Cost You Paid (auto from Orders) | T6: REAL Profit incl. Delivery (Tk) | U6: Profit for WHOLE Invoice (Tk) | V6: Helper - online invoice order | W6: Helper - sorted position | X6: Helper - line no. within month | Y6: Helper - month key | AA6: Item code list (feeds the dropdown — do not type here)
A7: 46219 | B7: Sale | C7: Online | D7: Samreen islam | E7: PAWF-260715-04EAA | F7: FD-DRY-SMHRT-15KG-001 | G7: =IF($F7="","",IFERROR(VLOOKUP($F7,Inventory!$A:$B,2,FALSE),"")) -> Smart Heart Adult Cat Food Chicken & Tuna [15kg] | H7: 1 | I7: =IF($F7="","",IF($B7="Gift",0,J7-IF(K7="",0,K7))) -> 6400 | J7: =IF($F7="","",IFERROR(VLOOKUP($F7,Inventory!$A:$K,11,FALSE),0)) -> 6700 | K7: 300 | L7: =IF($F7="","",IF($B7="Return",-H7*I7,H7*I7)) -> 6400 | M7: Paid | N7: =IF($F7="","",IFERROR(VLOOKUP($F7,Inventory!$A:$I,9,FALSE),0)) -> 5700 | O7: =IF($F7="","",IF($B7="Return",-H7*N7,H7*N7)) -> 5700 | P7: =IF($F7="","",L7-O7) -> 700 | R7: =IF($E7="","",IF(COUNTIF($E$7:$E7,$E7)>1,"",IFERROR(VLOOKUP($E7,Orders!$A:$I,8,FALSE),""))) -> 200 | S7: =IF($E7="","",IF(COUNTIF($E$7:$E7,$E7)>1,"",IFERROR(VLOOKUP($E7,Orders!$A:$I,9,FALSE),""))) -> 200 | T7: =IF($F7="","",P7+IF(R7="",0,R7)-IF(S7="",0,S7)) -> 700 | U7: =IF($F7="","",IF($E7="",T7,SUMIF(Sales!$E$7:$E$1506,$E7,Sales!$T$7:$T$1506))) -> 1100 | V7: =IF(OR($C7<>"Online",$E7=""),"",IF(COUNTIF($E$7:$E7,$E7)>1,"",COUNT($V$6:V6)+1)) -> 1 | W7: {=IF($V7="","",SUMPRODUCT((Sales!$V$7:$V$1506<>"")*(Sales!$E$7:$E$1506<$E7))+1)} -> 2 | X7: =IF($A7="","",COUNTIFS($A$7:$A7,">="&EOMONTH($A7,-1)+1,$A$7:$A7,"<="&EOMONTH($A7,0))) -> 1 | Y7: =IF($A7="","",TEXT($A7,"yyyymm")&"-"&$X7) -> 202607-1 | AA7: =IF(Inventory!A5="","",Inventory!A5) -> AC-PNC-LR-002
A8: 46219 | B8: Sale | C8: Online | D8: Samreen islam | E8: PAWF-260715-04EAA | F8: FD-DRY-SMHRT-10KG-001 | G8: =IF($F8="","",IFERROR(VLOOKUP($F8,Inventory!$A:$B,2,FALSE),"")) -> Smart Heart 10KG Chicken & Tuna | H8: 2 | I8: =IF($F8="","",IF($B8="Gift",0,J8-IF(K8="",0,K8))) -> 4300 | J8: =IF($F8="","",IFERROR(VLOOKUP($F8,Inventory!$A:$K,11,FALSE),0)) -> 4700 | K8: 400 | L8: =IF($F8="","",IF($B8="Return",-H8*I8,H8*I8)) -> 8600 | M8: Paid | N8: =IF($F8="","",IFERROR(VLOOKUP($F8,Inventory!$A:$I,9,FALSE),0)) -> 4100 | O8: =IF($F8="","",IF($B8="Return",-H8*N8,H8*N8)) -> 8200 | P8: =IF($F8="","",L8-O8) -> 400 | R8: =IF($E8="","",IF(COUNTIF($E$7:$E8,$E8)>1,"",IFERROR(VLOOKUP($E8,Orders!$A:$I,8,FALSE),""))) | S8: =IF($E8="","",IF(COUNTIF($E$7:$E8,$E8)>1,"",IFERROR(VLOOKUP($E8,Orders!$A:$I,9,FALSE),""))) | T8: =IF($F8="","",P8+IF(R8="",0,R8)-IF(S8="",0,S8)) -> 400 | U8: =IF($F8="","",IF($E8="",T8,SUMIF(Sales!$E$7:$E$1506,$E8,Sales!$T$7:$T$1506))) -> 1100 | V8: =IF(OR($C8<>"Online",$E8=""),"",IF(COUNTIF($E$7:$E8,$E8)>1,"",COUNT($V$6:V7)+1)) | W8: {=IF($V8="","",SUMPRODUCT((Sales!$V$7:$V$1506<>"")*(Sales!$E$7:$E$1506<$E8))+1)} | X8: =IF($A8="","",COUNTIFS($A$7:$A8,">="&EOMONTH($A8,-1)+1,$A$7:$A8,"<="&EOMONTH($A8,0))) -> 2 | Y8: =IF($A8="","",TEXT($A8,"yyyymm")&"-"&$X8) -> 202607-2 | AA8: =IF(Inventory!A6="","",Inventory!A6) -> AC-CTOY-004
A9: 46216 | B9: Sale | C9: Online | D9: Johura Hoque | E9: PAWF-260713-BAADD | F9: AC-CJ-AR-001 | G9: =IF($F9="","",IFERROR(VLOOKUP($F9,Inventory!$A:$B,2,FALSE),"")) -> Cat Jersey Argentina Medium | H9: 2 | I9: =IF($F9="","",IF($B9="Gift",0,J9-IF(K9="",0,K9))) -> 282 | J9: =IF($F9="","",IFERROR(VLOOKUP($F9,Inventory!$A:$K,11,FALSE),0)) -> 300 | K9: 18 | L9: =IF($F9="","",IF($B9="Return",-H9*I9,H9*I9)) -> 564 | M9: Paid | N9: =IF($F9="","",IFERROR(VLOOKUP($F9,Inventory!$A:$I,9,FALSE),0)) -> 140 | O9: =IF($F9="","",IF($B9="Return",-H9*N9,H9*N9)) -> 280 | P9: =IF($F9="","",L9-O9) -> 284 | Q9: Bkash | R9: =IF($E9="","",IF(COUNTIF($E$7:$E9,$E9)>1,"",IFERROR(VLOOKUP($E9,Orders!$A:$I,8,FALSE),""))) -> 80 | S9: =IF($E9="","",IF(COUNTIF($E$7:$E9,$E9)>1,"",IFERROR(VLOOKUP($E9,Orders!$A:$I,9,FALSE),""))) -> 36 | T9: =IF($F9="","",P9+IF(R9="",0,R9)-IF(S9="",0,S9)) -> 328 | U9: =IF($F9="","",IF($E9="",T9,SUMIF(Sales!$E$7:$E$1506,$E9,Sales!$T$7:$T$1506))) -> 328 | V9: =IF(OR($C9<>"Online",$E9=""),"",IF(COUNTIF($E$7:$E9,$E9)>1,"",COUNT($V$6:V8)+1)) -> 2 | W9: {=IF($V9="","",SUMPRODUCT((Sales!$V$7:$V$1506<>"")*(Sales!$E$7:$E$1506<$E9))+1)} -> 1 | X9: =IF($A9="","",COUNTIFS($A$7:$A9,">="&EOMONTH($A9,-1)+1,$A$7:$A9,"<="&EOMONTH($A9,0))) -> 3 | Y9: =IF($A9="","",TEXT($A9,"yyyymm")&"-"&$X9) -> 202607-3 | AA9: =IF(Inventory!A7="","",Inventory!A7) -> AC-CB-001
A10: 46221 | B10: Sale | C10: Online | D10: Nadim | E10: PAWF-260718-8CA86 | F10: FD-DRY-SMHRT-15KG-001 | G10: =IF($F10="","",IFERROR(VLOOKUP($F10,Inventory!$A:$B,2,FALSE),"")) -> Smart Heart Adult Cat Food Chicken & Tuna [15kg] | H10: 1 | I10: =IF($F10="","",IF($B10="Gift",0,J10-IF(K10="",0,K10))) -> 6100 | J10: =IF($F10="","",IFERROR(VLOOKUP($F10,Inventory!$A:$K,11,FALSE),0)) -> 6700 | K10: 600 | L10: =IF($F10="","",IF($B10="Return",-H10*I10,H10*I10)) -> 6100 | M10: Paid | N10: =IF($F10="","",IFERROR(VLOOKUP($F10,Inventory!$A:$I,9,FALSE),0)) -> 5700 | O10: =IF($F10="","",IF($B10="Return",-H10*N10,H10*N10)) -> 5700 | P10: =IF($F10="","",L10-O10) -> 400 | R10: =IF($E10="","",IF(COUNTIF($E$7:$E10,$E10)>1,"",IFERROR(VLOOKUP($E10,Orders!$A:$I,8,FALSE),""))) -> 0 | S10: =IF($E10="","",IF(COUNTIF($E$7:$E10,$E10)>1,"",IFERROR(VLOOKUP($E10,Orders!$A:$I,9,FALSE),""))) -> 0 | T10: =IF($F10="","",P10+IF(R10="",0,R10)-IF(S10="",0,S10)) -> 400 | U10: =IF($F10="","",IF($E10="",T10,SUMIF(Sales!$E$7:$E$1506,$E10,Sales!$T$7:$T$1506))) -> 220 | V10: =IF(OR($C10<>"Online",$E10=""),"",IF(COUNTIF($E$7:$E10,$E10)>1,"",COUNT($V$6:V9)+1)) -> 3 | W10: {=IF($V10="","",SUMPRODUCT((Sales!$V$7:$V$1506<>"")*(Sales!$E$7:$E$1506<$E10))+1)} -> 3 | X10: =IF($A10="","",COUNTIFS($A$7:$A10,">="&EOMONTH($A10,-1)+1,$A$7:$A10,"<="&EOMONTH($A10,0))) -> 4 | Y10: =IF($A10="","",TEXT($A10,"yyyymm")&"-"&$X10) -> 202607-4 | AA10: =IF(Inventory!A8="","",Inventory!A8) -> PO-WET-NK-70G-001
A11: 46210 | B11: Sale | C11: Shop | D11: PawfectBD Shop | E11: PAWF-260719-979C1 | F11: TR-CRMY-15G-001 | G11: =IF($F11="","",IFERROR(VLOOKUP($F11,Inventory!$A:$B,2,FALSE),"")) -> Creamy Treat 15G (Purry & Hyper Paws) | H11: 40 | I11: =IF($F11="","",IF($B11="Gift",0,J11-IF(K11="",0,K11))) -> 19.5 | J11: =IF($F11="","",IFERROR(VLOOKUP($F11,Inventory!$A:$K,11,FALSE),0)) -> 20 | K11: 0.5 | L11: =IF($F11="","",IF($B11="Return",-H11*I11,H11*I11)) -> 780 | M11: Paid | N11: =IF($F11="","",IFERROR(VLOOKUP($F11,Inventory!$A:$I,9,FALSE),0)) -> 8.1474119 | O11: =IF($F11="","",IF($B11="Return",-H11*N11,H11*N11)) -> 325.89647 | P11: =IF($F11="","",L11-O11) -> 454.10353 | R11: =IF($E11="","",IF(COUNTIF($E$7:$E11,$E11)>1,"",IFERROR(VLOOKUP($E11,Orders!$A:$I,8,FALSE),""))) | S11: =IF($E11="","",IF(COUNTIF($E$7:$E11,$E11)>1,"",IFERROR(VLOOKUP($E11,Orders!$A:$I,9,FALSE),""))) | T11: =IF($F11="","",P11+IF(R11="",0,R11)-IF(S11="",0,S11)) -> 454.10353 | U11: =IF($F11="","",IF($E11="",T11,SUMIF(Sales!$E$7:$E$1506,$E11,Sales!$T$7:$T$1506))) -> 908.20705 | V11: =IF(OR($C11<>"Online",$E11=""),"",IF(COUNTIF($E$7:$E11,$E11)>1,"",COUNT($V$6:V10)+1)) | W11: {=IF($V11="","",SUMPRODUCT((Sales!$V$7:$V$1506<>"")*(Sales!$E$7:$E$1506<$E11))+1)} | X11: =IF($A11="","",COUNTIFS($A$7:$A11,">="&EOMONTH($A11,-1)+1,$A$7:$A11,"<="&EOMONTH($A11,0))) -> 5 | Y11: =IF($A11="","",TEXT($A11,"yyyymm")&"-"&$X11) -> 202607-5 | AA11: =IF(Inventory!A9="","",Inventory!A9) -> AC-CJ-AR-001
A12: 46211 | B12: Sale | C12: Shop | D12: PawfectBD Shop | E12: PAWF-260719-979C1 | F12: TR-CRMY-15G-001 | G12: =IF($F12="","",IFERROR(VLOOKUP($F12,Inventory!$A:$B,2,FALSE),"")) -> Creamy Treat 15G (Purry & Hyper Paws) | H12: 40 | I12: =IF($F12="","",IF($B12="Gift",0,J12-IF(K12="",0,K12))) -> 19.5 | J12: =IF($F12="","",IFERROR(VLOOKUP($F12,Inventory!$A:$K,11,FALSE),0)) -> 20 | K12: 0.5 | L12: =IF($F12="","",IF($B12="Return",-H12*I12,H12*I12)) -> 780 | M12: Paid | N12: =IF($F12="","",IFERROR(VLOOKUP($F12,Inventory!$A:$I,9,FALSE),0)) -> 8.1474119 | O12: =IF($F12="","",IF($B12="Return",-H12*N12,H12*N12)) -> 325.89647 | P12: =IF($F12="","",L12-O12) -> 454.10353 | R12: =IF($E12="","",IF(COUNTIF($E$7:$E12,$E12)>1,"",IFERROR(VLOOKUP($E12,Orders!$A:$I,8,FALSE),""))) | S12: =IF($E12="","",IF(COUNTIF($E$7:$E12,$E12)>1,"",IFERROR(VLOOKUP($E12,Orders!$A:$I,9,FALSE),""))) | T12: =IF($F12="","",P12+IF(R12="",0,R12)-IF(S12="",0,S12)) -> 454.10353 | U12: =IF($F12="","",IF($E12="",T12,SUMIF(Sales!$E$7:$E$1506,$E12,Sales!$T$7:$T$1506))) -> 908.20705 | V12: =IF(OR($C12<>"Online",$E12=""),"",IF(COUNTIF($E$7:$E12,$E12)>1,"",COUNT($V$6:V11)+1)) | W12: {=IF($V12="","",SUMPRODUCT((Sales!$V$7:$V$1506<>"")*(Sales!$E$7:$E$1506<$E12))+1)} | X12: =IF($A12="","",COUNTIFS($A$7:$A12,">="&EOMONTH($A12,-1)+1,$A$7:$A12,"<="&EOMONTH($A12,0))) -> 6 | Y12: =IF($A12="","",TEXT($A12,"yyyymm")&"-"&$X12) -> 202607-6 | AA12: =IF(Inventory!A10="","",Inventory!A10) -> AC-CJ-AR-002
A13: 46212 | B13: Sale | C13: Shop | D13: PawfectBD Shop | E13: PAWF-260719-FCE0C | F13: FD-DRY-CHNK-OCFCK-1.5KG-001 | G13: =IF($F13="","",IFERROR(VLOOKUP($F13,Inventory!$A:$B,2,FALSE),"")) -> Chonk All ages Ocean Fish with Chicken | H13: 1 | I13: =IF($F13="","",IF($B13="Gift",0,J13-IF(K13="",0,K13))) -> 500 | J13: =IF($F13="","",IFERROR(VLOOKUP($F13,Inventory!$A:$K,11,FALSE),0)) -> 500 | L13: =IF($F13="","",IF($B13="Return",-H13*I13,H13*I13)) -> 500 | M13: Paid | N13: =IF($F13="","",IFERROR(VLOOKUP($F13,Inventory!$A:$I,9,FALSE),0)) -> 400 | O13: =IF($F13="","",IF($B13="Return",-H13*N13,H13*N13)) -> 400 | P13: =IF($F13="","",L13-O13) -> 100 | R13: =IF($E13="","",IF(COUNTIF($E$7:$E13,$E13)>1,"",IFERROR(VLOOKUP($E13,Orders!$A:$I,8,FALSE),""))) | S13: =IF($E13="","",IF(COUNTIF($E$7:$E13,$E13)>1,"",IFERROR(VLOOKUP($E13,Orders!$A:$I,9,FALSE),""))) | T13: =IF($F13="","",P13+IF(R13="",0,R13)-IF(S13="",0,S13)) -> 100 | U13: =IF($F13="","",IF($E13="",T13,SUMIF(Sales!$E$7:$E$1506,$E13,Sales!$T$7:$T$1506))) -> 300 | V13: =IF(OR($C13<>"Online",$E13=""),"",IF(COUNTIF($E$7:$E13,$E13)>1,"",COUNT($V$6:V12)+1)) | W13: {=IF($V13="","",SUMPRODUCT((Sales!$V$7:$V$1506<>"")*(Sales!$E$7:$E$1506<$E13))+1)} | X13: =IF($A13="","",COUNTIFS($A$7:$A13,">="&EOMONTH($A13,-1)+1,$A$7:$A13,"<="&EOMONTH($A13,0))) -> 7 | Y13: =IF($A13="","",TEXT($A13,"yyyymm")&"-"&$X13) -> 202607-7 | AA13: =IF(Inventory!A11="","",Inventory!A11) -> AC-CJ-BR-002
